Workbook
Name Slicer_Condition: #N/A
Name Slicer_Model_family: #N/A
Name Slicer_Storage_gb_numeric: #N/A

Sheet Backmarket
A1: Platform | B1: Model | C1: Condition | D1: Sold | E1: Price | F1: New | G1: Revenue
A2: Backmarket | B2: iPhone 15 Plus | C2: Unlocked | D2: 1102 | E2: 389.99 | F2: 829 | G2: =Table1_2[[#This Row],[Sold]]*Table1_2[[#This Row],[Price]] -> 429768.98
A3: Backmarket | B3: iPhone 16 | C3: Unlocked | D3: 387 | E3: 561 | F3: 729 | G3: =Table1_2[[#This Row],[Sold]]*Table1_2[[#This Row],[Price]] -> 217107
A4: Backmarket | B4: iPhone 15 | C4: Unlocked | D4: 1901 | E4: 368 | F4: 729 | G4: =Table1_2[[#This Row],[Sold]]*Table1_2[[#This Row],[Price]] -> 699568
A5: Backmarket | B5: iPhone 15 Pro | C5: Unlocked | D5: 1507 | E5: 459.99 | F5: 999 | G5: =Table1_2[[#This Row],[Sold]]*Table1_2[[#This Row],[Price]] -> 693204.93
A6: Backmarket | B6: iPhone 15 Pro Max | C6: Unlocked | D6: 1220 | E6: 589.99 | F6: 1199 | G6: =Table1_2[[#This Row],[Sold]]*Table1_2[[#This Row],[Price]] -> 719787.8
A7: Backmarket | B7: iPhone 17 | C7: Unlocked | D7: 76 | E7: 689 | F7: 829 | G7: =Table1_2[[#This Row],[Sold]]*Table1_2[[#This Row],[Price]] -> 52364
A8: Backmarket | B8: iPhone 17 Pro Max | C8: Unlocked | D8: 71 | E8: 1398 | F8: 0 | G8: =Table1_2[[#This Row],[Sold]]*Table1_2[[#This Row],[Price]] -> 99258
A9: Backmarket | B9: iPhone 14 | C9: Unlocked | D9: 3871 | E9: 263 | F9: 629 | G9: =Table1_2[[#This Row],[Sold]]*Table1_2[[#This Row],[Price]] -> 1018073
A10: Backmarket | B10: iPhone 13 | C10: Unlocked | D10: 5635 | E10: 230 | F10: 629 | G10: =Table1_2[[#This Row],[Sold]]*Table1_2[[#This Row],[Price]] -> 1296050
A11: Backmarket | B11: iPhone 13 mini | C11: Unlocked | D11: 2243 | E11: 210 | F11: 629 | G11: =Table1_2[[#This Row],[Sold]]*Table1_2[[#This Row],[Price]] -> 471030
A12: Backmarket | B12: iPhone 14 Plus | C12: Unlocked | D12: 1619 | E12: 304 | F12: 729 | G12: =Table1_2[[#This Row],[Sold]]*Table1_2[[#This Row],[Price]] -> 492176
A13: Backmarket | B13: iPhone 14 Pro Max | C13: Unlocked | D13: 1574 | E13: 444 | F13: 1099 | G13: =Table1_2[[#This Row],[Sold]]*Table1_2[[#This Row],[Price]] -> 698856
... A15: Backmarket | B15: iPhone 12 | C15: Unlocked | D15: 9302 | E15: 171 | F15: 629 | G15: =Table1_2[[#This Row],[Sold]]*Table1_2[[#This Row],[Price]] -> 1590642
A16: Backmarket | B16: iPhone 12 mini | C16: Unlocked | D16: 4052 | E16: 146 | F16: $459 | G16: =Table1_2[[#This Row],[Sold]]*Table1_2[[#This Row],[Price]] -> 591592
A17: Backmarket | B17: iPhone 12 Pro | C17: Unlocked | D17: 3617 | E17: 243.6 | F17: $799 | G17: =Table1_2[[#This Row],[Sold]]*Table1_2[[#This Row],[Price]] -> 881101.2
A18: Backmarket | B18: iPhone 12 Pro Max | C18: Unlocked | D18: 3248 | E18: 319 | F18: $899 | G18: =Table1_2[[#This Row],[Sold]]*Table1_2[[#This Row],[Price]] -> 1036112
A19: Backmarket | B19: iPhone 15 | C19: Locked AT&T | D19: 39 | E19: 347 | F19: $729 | G19: =Table1_2[[#This Row],[Sold]]*Table1_2[[#This Row],[Price]] -> 13533
A20: Backmarket | B20: iPhone 14 | C20: Locked AT&T | D20: 96 | E20: 265 | F20: $629 | G20: =Table1_2[[#This Row],[Sold]]*Table1_2[[#This Row],[Price]] -> 25440
A21: Backmarket | B21: iPhone 12 | C21: Locked AT&T | D21: 367 | E21: 173.99 | F21: $629 | G21: =Table1_2[[#This Row],[Sold]]*Table1_2[[#This Row],[Price]] -> 63854.33
A22: Backmarket | B22: iPhone 13 | C22: Locked AT&T | D22: 223 | E22: 239 | F22: $629 | G22: =Table1_2[[#This Row],[Sold]]*Table1_2[[#This Row],[Price]] -> 53297
A23: Backmarket | B23: iPhone 14 | C23: Locked T-Mobile | D23: 85 | E23: 269 | F23: $599 | G23: =Table1_2[[#This Row],[Sold]]*Table1_2[[#This Row],[Price]] -> 22865
A24: Backmarket | B24: iPhone 13 | C24: Locked T-Mobile | D24: 111 | E24: 238 | F24: $599 | G24: =Table1_2[[#This Row],[Sold]]*Table1_2[[#This Row],[Price]] -> 26418
A25: Backmarket | B25: iPhone 15 | C25: Locked T-Mobile | D25: 47 | E25: 384 | F25: $699 | G25: =Table1_2[[#This Row],[Sold]]*Table1_2[[#This Row],[Price]] -> 18048
A26: Backmarket | B26: iPhone 15 Pro | C26: Locked AT&T | D26: 21 | E26: 443 | F26: $999 | G26: =Table1_2[[#This Row],[Sold]]*Table1_2[[#This Row],[Price]] -> 9303
A27: Backmarket | B27: iPhone 16 | C27: Locked Verizon | D27: 3 | E27: 475 | F27: $729 | G27: =Table1_2[[#This Row],[Sold]]*Table1_2[[#This Row],[Price]] -> 1425
... A50: Backmarket | B50: iPhone 17 Pro Max | C50: Locked AT&T | D50: 1 | E50: 980 | F50: $1,199 | G50: =Table1_2[[#This Row],[Sold]]*Table1_2[[#This Row],[Price]] -> 980
A51: Backmarket | B51: iPhone 12 mini | C51: Locked AT&T | D51: 110 | E51: 153 | F51: 459 | G51: =Table1_2[[#This Row],[Sold]]*Table1_2[[#This Row],[Price]] -> 16830
A52: Backmarket | B52: iPhone 12 mini | C52: Locked Verizon | D52: 44 | E52: 158 | F52: 459 | G52: =Table1_2[[#This Row],[Sold]]*Table1_2[[#This Row],[Price]] -> 6952
A53: Backmarket | B53: iPhone 12 mini | C53: Locked T-Mobile | D53: 72 | E53: 195 | F53: 549 | G53: =Table1_2[[#This Row],[Sold]]*Table1_2[[#This Row],[Price]] -> 14040
A54: Backmarket | B54: iPhone 13 mini | C54: Locked AT&T | D54: 21 | E54: 249 | F54: 729 | G54: =Table1_2[[#This Row],[Sold]]*Table1_2[[#This Row],[Price]] -> 5229
A55: Backmarket | B55: iPhone 13 mini | C55: Locked T-Mobile | D55: 34 | E55: 256 | F55: 599 | G55: =Table1_2[[#This Row],[Sold]]*Table1_2[[#This Row],[Price]] -> 8704
A56: Backmarket | B56: iPhone 13 | C56: Locked Verizon | D56: 52 | E56: 264.5 | F56: 599 | G56: =Table1_2[[#This Row],[Sold]]*Table1_2[[#This Row],[Price]] -> 13754
A57: Backmarket | B57: iPhone 12 Pro | C57: Locked AT&T | D57: 58 | E57: 270.68 | F57: 799 | G57: =Table1_2[[#This Row],[Sold]]*Table1_2[[#This Row],[Price]] -> 15699.44
A58: Backmarket | B58: iPhone 12 Pro | C58: Locked Verizon | D58: 23 | E58: 270.68 | F58: 799 | G58: =Table1_2[[#This Row],[Sold]]*Table1_2[[#This Row],[Price]] -> 6225.64
A59: Backmarket | B59: iPhone 12 Pro | C59: Locked T-Mobile | D59: 35 | E59: 271.68 | F59: 799 | G59: =Table1_2[[#This Row],[Sold]]*Table1_2[[#This Row],[Price]] -> 9508.8
A60: Backmarket | B60: iPhone 13 mini | C60: Locked Verizon | D60: 13 | E60: 284 | F60: 629 | G60: =Table1_2[[#This Row],[Sold]]*Table1_2[[#This Row],[Price]] -> 3692
A61: Backmarket | B61: iPhone 14 Plus | C61: Locked T-Mobile | D61: 41 | E61: 291 | F61: 699 | G61: =Table1_2[[#This Row],[Sold]]*Table1_2[[#This Row],[Price]] -> 11931
A62: Backmarket | B62: iPhone 12 Pro Max | C62: Locked T-Mobile | D62: 55 | E62: 307 | F62: 899 | G62: =Table1_2[[#This Row],[Sold]]*Table1_2[[#This Row],[Price]] -> 16885
... A69: Backmarket | B69: iPhone 17 Pro Max | C69: Locked Verizon | D69: 0 | E69: 1179 | F69: 0 | G69: =Table1_2[[#This Row],[Sold]]*Table1_2[[#This Row],[Price]] -> 0
...

Sheet eBay
A1: Platform2 | B1: Model | C1: Model Family | D1: Warranty | E1: Condition | F1: Ratings | G1: reviews | H1: Price | I1: Delivery charge | J1: Total Price | K1: Location | L1: Sold | M1: Discount | N1: Carriers | O1: Reviews2 | P1: Revenue
A2: eBay | B2: Apple iPhone 12 128GB - Fully Unlocked - VERY GOOD Condition | C2: iPhone 12 | D2: 1 YEAR WARRANTY🔥 FREE RETURNS🔥FREE 2 DAY SHIPPING | E2: Excellent | F2: 4.5 | G2: 54 | H2: 211.2 | I2: 92.33 | J2: =Table1_4[[#This Row],[Price]]+Table1_4[[#This Row],[Delivery charge]] -> 303.53 | K2: United States | L2: 744 | M2: $5 off every 2 items with coupon | N2: gadget-solutions | O2: 99.4% positive (21.8K) | P2: =Table1_4[[#This Row],[Total Price]]*Table1_4[[#This Row],[ Sold]] -> 225826.32
A3: eBay | B3: Apple iPhone 14 128GB - Fully Unlocked - VERY GOOD Condition | C3: iPhone 14 | D3: 1 YEAR WARRANTY🔥 FREE RETURNS🔥FREE 2 DAY SHIPPING | E3: Very Good | F3: 4.5 | G3: 17 | H3: 283.2 | I3: 108.89 | J3: =Table1_4[[#This Row],[Price]]+Table1_4[[#This Row],[Delivery charge]] -> 392.09 | K3: United States | L3: 494 | M3: $5 off every 2 items with coupon | N3: gadget-solutions | O3: 99.4% positive (21.8K) | P3: =Table1_4[[#This Row],[Total Price]]*Table1_4[[#This Row],[ Sold]] -> 193692.46
A4: eBay | B4: Apple iPhone 12 Mini 128GB Fully Unlocked - VERY GOOD Condition | C4: iPhone 12 Mini | D4: No Warranty | E4: Very Good | F4: 5 | G4: 31 | H4: 170.9 | I4: 83.07 | J4: =Table1_4[[#This Row],[Price]]+Table1_4[[#This Row],[Delivery charge]] -> 253.97 | K4: United States | L4: 326 | M4: $5 off every 2 items with coupon | N4: gadget-solutions | O4: 99.4% positive (21.8K) | P4: =Table1_4[[#This Row],[Total Price]]*Table1_4[[#This Row],[ Sold]] -> 82794.22
A5: eBay | B5: Apple iPhone 15 128GB - Fully Unlocked- VERY GOOD Condition | C5: iPhone 15 | D5: 1 YEAR WARRANTY🔥 FREE RETURNS🔥FREE FEDEX 2 DAY | E5: Very Good | F5: 5 | G5: 5 | H5: 396.5 | I5: 134.95 | J5: =Table1_4[[#This Row],[Price]]+Table1_4[[#This Row],[Delivery charge]] -> 531.45 | K5: United States | L5: 115 | M5: $5 off every 2 items with coupon | N5: gadget-solutions | O5: 99.4% positive (21.8K) | P5: =Table1_4[[#This Row],[Total Price]]*Table1_4[[#This Row],[ Sold]] -> 61116.75
A6: eBay | B6: Apple iPhone 14 128GB Midnight Factory Unlocked (1-Year Warranty) Good | C6: iPhone 14 | D6: 1-Year Warranty🔵FREE RETURNS🟡U.S SELLER🔴 | E6: Good | F6: 5 | G6: 84 | H6: 254.99 | I6: 105.03 | J6: =Table1_4[[#This Row],[Price]]+Table1_4[[#This Row],[Delivery charge]] -> 360.02 | K6: United States | L6: 79 | M6: No Discount | N6: qualitycellz | O6: 100% positive (172K) | P6: =Table1_4[[#This Row],[Total Price]]*Table1_4[[#This Row],[ Sold]] -> 28441.58
A7: eBay | B7: Apple iPhone 14 128GB Factory Unlocked Very Good | C7: iPhone 14 | D7: 12-MONTH WARRANTY • FREE FAST SHIPPING • 30 DAY RETURNS | E7: Very Good | F7: 4.5 | G7: 17 | H7: 265 | I7: 104.71 | J7: =Table1_4[[#This Row],[Price]]+Table1_4[[#This Row],[Delivery charge]] -> 369.71 | K7: United States | L7: 17 | M7: No Discount | N7: savaydeals | O7: 99.8% positive (16.6K) | P7: =Table1_4[[#This Row],[Total Price]]*Table1_4[[#This Row],[ Sold]] -> 6285.07
A8: eBay | B8: Apple iPhone 12 Mini, 64/128/256GB - Unlocked- Refurbished Excellent | C8: iPhone 12 Mini | D8: No Warranty | E8: Excellent | F8: 5 | G8: 31 | H8: 189.99 | I8: 93.53 | J8: =Table1_4[[#This Row],[Price]]+Table1_4[[#This Row],[Delivery charge]] -> 283.52 | K8: United States | L8: 57 | M8: No Discount | N8: electronicdea1s | O8: 98.9% positive (34.9K) | P8: =Table1_4[[#This Row],[Total Price]]*Table1_4[[#This Row],[ Sold]] -> 16160.64
A9: eBay | B9: Apple iPhone 12 Purple 64GB Good - Refurbished - Unlocked | C9: iPhone 12 | D9: No Warranty | E9: Good | F9: 5 | G9: 23 | H9: 175.56 | I9: 84.14 | J9: =Table1_4[[#This Row],[Price]]+Table1_4[[#This Row],[Delivery charge]] -> 259.7 | K9: United States | L9: 195 | M9: No Discount | N9: verizon | O9: 99.5% positive (25.7K) | P9: =Table1_4[[#This Row],[Total Price]]*Table1_4[[#This Row],[ Sold]] -> 50641.5
A10: eBay | B10: Apple iPhone 12 Red 64GB Good - Refurbished - Unlocked | C10: iPhone 12 | D10: No Warranty | E10: Good | F10: 4 | G10: 11 | H10: 168.58 | I10: 82.53 | J10: =Table1_4[[#This Row],[Price]]+Table1_4[[#This Row],[Delivery charge]] -> 251.11 | K10: United States | L10: 138 | M10: No Discount | N10: verizon | O10: 99.5% positive (25.7K) | P10: =Table1_4[[#This Row],[Total Price]]*Table1_4[[#This Row],[ Sold]] -> 34653.18
A11: eBay | B11: Apple iPhone 12, 64/128/256GB - Unlocked - Refurbished Excellent | C11: iPhone 12 | D11: No Warranty | E11: Excellent | H11: 219.99 | I11: 96.98 | J11: =Table1_4[[#This Row],[Price]]+Table1_4[[#This Row],[Delivery charge]] -> 316.97 | K11: United States | L11: 34 | M11: No Discount | N11: electronicdea1s | O11: 98.9% positive (34.9K) | P11: =Table1_4[[#This Row],[Total Price]]*Table1_4[[#This Row],[ Sold]] -> 10776.98
A12: eBay | B12: Apple iPhone 14 Plus A2632 128GB Unlocked - Excellent Refurbished | C12: iPhone 14 Plus | D12: No Warranty | E12: Excellent | F12: 4.5 | G12: 25 | H12: 303.99 | I12: 113.68 | J12: =Table1_4[[#This Row],[Price]]+Table1_4[[#This Row],[Delivery charge]] -> 417.67 | K12: United States | L12: 26 | M12: No Discount | N12: cellularstream | O12: 98.8% positive (173.8K) | P12: =Table1_4[[#This Row],[Total Price]]*Table1_4[[#This Row],[ Sold]] -> 10859.42
A13: eBay | B13: Apple iPhone 12 Blue 128GB Good - Refurbished - Unlocked | C13: iPhone 12 | D13: No Warranty | E13: Good | F13: 4.5 | G13: 54 | H13: 192.99 | I13: 88.15 | J13: =Table1_4[[#This Row],[Price]]+Table1_4[[#This Row],[Delivery charge]] -> 281.14 | K13: United States | L13: 197 | M13: No Discount | N13: verizon | O13: 99.5% positive (25.7K) | P13: =Table1_4[[#This Row],[Total Price]]*Table1_4[[#This Row],[ Sold]] -> 55384.58
A14: eBay | B14: Apple iPhone 12 64GB – Fully Unlocked - VERY GOOD CONDITION - Unlocked | C14: iPhone 12 | D14: 1 YEAR WARRANTY🔥 FREE RETURNS🔥FREE 2 DAY SHIPPING | E14: Very Good | F14: 4.5 | G14: 89 | H14: 182.4 | I14: 85.71 | J14: =Table1_4[[#This Row],[Price]]+Table1_4[[#This Row],[Delivery charge]] -> 268.11 | K14: United States | L14: 2808 | M14: $5 off every 2 items with coupon | N14: gadget-solutions | O14: 99.4% positive (21.8K) | P14: =Table1_4[[#This Row],[Total Price]]*Table1_4[[#This Row],[ Sold]] -> 752852.88
A15: eBay | B15: Apple iPhone 12 Mini 64GB - Fully Unlocked - EXCELLENT Condition | C15: iPhone 12 Mini | D15: No Warranty | E15: Excellent | F15: 4.5 | G15: 18 | H15: 168 | I15: 82.4 | J15: =Table1_4[[#This Row],[Price]]+Table1_4[[#This Row],[Delivery charge]] -> 250.4 | K15: United States | L15: 6 | M15: $5 off every 2 items with coupon | N15: gadget-solutions | O15: 99.4% positive (21.8K) | P15: =Table1_4[[#This Row],[Total Price]]*Table1_4[[#This Row],[ Sold]] -> 1502.4
A16: eBay | B16: Apple iPhone 15 Plus 128GB - Fully Unlocked - VERY GOOD Condition | C16: iPhone 15 Plus | D16: No Warranty | E16: Very Good | F16: 4.5 | G16: 4 | H16: 398.4 | I16: 135.39 | J16: =Table1_4[[#This Row],[Price]]+Table1_4[[#This Row],[Delivery charge]] -> 533.79 | K16: United States | L16: 107 | M16: $5 off every 2 items with coupon | N16: gadget-solutions | O16: 99.4% positive (21.8K) | P16: =Table1_4[[#This Row],[Total Price]]*Table1_4[[#This Row],[ Sold]] -> 57115.53
A17: eBay | B17: Apple iPhone 12 Pro 256GB - Fully Unlocked - VERY GOOD Condition | C17: iPhone 12 Pro | D17: No Warranty | E17: Very Good | F17: 4.5 | G17: 37 | H17: 266.9 | I17: 105.15 | J17: =Table1_4[[#This Row],[Price]]+Table1_4[[#This Row],[Delivery charge]] -> 372.05 | K17: United States | L17: 43 | M17: $5 off every 2 items with coupon | N17: gadget-solutions | O17: 99.4% positive (21.8K) | P17: =Table1_4[[#This Row],[Total Price]]*Table1_4[[#This Row],[ Sold]] -> 15998.15
A18: eBay | B18: Apple iPhone 12 White 128GB Very Good - Refurbished - Unlocked | C18: iPhone 12 | D18: No Warranty | E18: Very Good | H18: 203.86 | I18: 90.65 | J18: =Table1_4[[#This Row],[Price]]+Table1_4[[#This Row],[Delivery charge]] -> 294.51 | K18: United States | L18: 116 | M18: No Discount | N18: verizon | O18: 99.5% positive (25.7K) | P18: =Table1_4[[#This Row],[Total Price]]*Table1_4[[#This Row],[ Sold]] -> 34163.16
A19: eBay | B19: Apple iPhone 12 256GB - Fully Unlocked - VERY GOOD Condition | C19: iPhone 12 | D19: 1 YEAR WARRANTY🔥 FREE RETURNS🔥FREE FEDEX 2 DAY | E19: Very Good | F19: 5 | G19: 19 | H19: 227.5 | I19: 96.08 | J19: =Table1_4[[#This Row],[Price]]+Table1_4[[#This Row],[Delivery charge]] -> 323.58 | K19: United States | L19: 188 | M19: $5 off every 2 items with coupon | N19: gadget-solutions | O19: 99.4% positive (21.8K) | P19: =Table1_4[[#This Row],[Total Price]]*Table1_4[[#This Row],[ Sold]] -> 60833.04
A20: eBay | B20: Apple iPhone 16 128GB Factory Unlocked Very Good Condition | C20: iPhone 16 | D20: 12-MONTH WARRANTY • FREE FAST SHIPPING • 30 DAY RETURNS | E20: Very Good | H20: 555 | I20: 158.46 | J20: =Table1_4[[#This Row],[Price]]+Table1_4[[#This Row],[Delivery charge]] -> 713.46 | K20: United States | L20: 0 | M20: No Discount | N20: savaydeals | O20: 99.8% positive (16.6K) | P20: =Table1_4[[#This Row],[Total Price]]*Table1_4[[#This Row],[ Sold]] -> 0
A21: eBay | B21: Apple iPhone 13 128GB Unlocked - Good | C21: iPhone 13 | D21: Free 2-Day Shipping - 1 Yr AllState Warranty - Cellfeee | E21: Good | F21: 4.5 | G21: 15 | H21: 225.99 | I21: 82.78 | J21: =Table1_4[[#This Row],[Price]]+Table1_4[[#This Row],[Delivery charge]] -> 308.77 | K21: United States | L21: 170 | M21: No Discount | N21: cellfeee | O21: 99.4% positive (184K) | P21: =Table1_4[[#This Row],[Total Price]]*Table1_4[[#This Row],[ Sold]] -> 52490.9
A22: eBay | B22: Apple iPhone 15 A2846 128GB Unlocked - Excellent Refurbished | C22: iPhone 15 | D22: No Warranty | E22: Excellent | H22: 388.99 | I22: 135.85 | J22: =Table1_4[[#This Row],[Price]]+Table1_4[[#This Row],[Delivery charge]] -> 524.84 | K22: United States | L22: 32 | M22: No Discount | N22: cellularstream | O22: 98.8% positive (173.8K) | P22: =Table1_4[[#This Row],[Total Price]]*Table1_4[[#This Row],[ Sold]] -> 16794.88
A23: eBay | B23: Apple iPhone 14 A2649 128GB Unlocked - Excellent Refurbished | C23: iPhone 14 | D23: No Warranty | E23: Excellent | F23: 4.5 | G23: 15 | H23: 298.99 | I23: 112.53 | J23: =Table1_4[[#This Row],[Price]]+Table1_4[[#This Row],[Delivery charge]] -> 411.52 | K23: United States | L23: 0 | M23: No Discount | N23: cellularstream | O23: 98.8% positive (173.8K) | P23: =Table1_4[[#This Row],[Total Price]]*Table1_4[[#This Row],[ Sold]] -> 0
A24: eBay | B24: Apple iPhone 15 A2846 128GB Unlocked - Very Good Refurbished | C24: iPhone 15 | D24: No Warranty | E24: Very Good | H24: 375.99 | I24: 132.86 | J24: =Table1_4[[#This Row],[Price]]+Table1_4[[#This Row],[Delivery charge]] -> 508.85 | K24: United States | L24: 17 | M24: No Discount | N24: cellularstream | O24: 98.8% positive (173.8K) | P24: =Table1_4[[#This Row],[Total Price]]*Table1_4[[#This Row],[ Sold]] -> 8650.45
A25: eBay | B25: Apple iPhone 13 256GB Factory Unlocked Very Good | C25: iPhone 13 | D25: 12-MONTH WARRANTY • FREE FAST SHIPPING • 30 DAY RETURNS | E25: Very Good | F25: 5 | G25: 5 | H25: 265 | I25: 91.76 | J25: =Table1_4[[#This Row],[Price]]+Table1_4[[#This Row],[Delivery charge]] -> 356.76 | K25: United States | L25: 0 | M25: No Discount | N25: savaydeals | O25: 99.8% positive (16.6K) | P25: =Table1_4[[#This Row],[Total Price]]*Table1_4[[#This Row],[ Sold]] -> 0
A26: eBay | B26: Apple iPhone 14 128GB Unlocked - Good | C26: iPhone 14 | D26: Free 2-Day Shipping - 1 Yr AllState Warranty - Cellfeee | E26: Good | F26: 5 | G26: 84 | H26: 258.99 | I26: 90.37 | J26: =Table1_4[[#This Row],[Price]]+Table1_4[[#This Row],[Delivery charge]] -> 349.36 | K26: United States | L26: 710 | M26: No Discount | N26: cellfeee | O26: 99.4% positive (184K) | P26: =Table1_4[[#This Row],[Total Price]]*Table1_4[[#This Row],[ Sold]] -> 248045.6
A27: eBay | B27: Apple iPhone 12 Mini 64GB - Fully Unlocked - VERY GOOD Condition | C27: iPhone 12 Mini | D27: 1 YEAR WARRANTY🔥 FREE RETURNS🔥FREE FAST SHIPPING | E27: Very Good | F27: 4.5 | G27: 18 | H27: 158.4 | I27: 80.19 | J27: =Table1_4[[#This Row],[Price]]+Table1_4[[#This Row],[Delivery charge]] -> 238.59 | K27: United States | L27: 341 | M27: $5 off every 2 items with coupon | N27: gadget-solutions | O27: 99.4% positive (21.8K) | P27: =Table1_4[[#This Row],[Total Price]]*Table1_4[[#This Row],[ Sold]] -> 81359.19
A28: eBay | B28: Apple iPhone 12 - 64GB-256GB - All Colors - Fully Unlocked - VERY GOOD Condition | C28: iPhone 12 | D28: No Warranty | E28: Very Good | F28: 4.5 | G28: 89 | H28: 187.99 | I28: 87 | J28: =Table1_4[[#This Row],[Price]]+Table1_4[[#This Row],[Delivery charge]] -> 274.99 | K28: United States | L28: 142 | M28: $5 off every 2 items with coupon | N28: gadget-solutions | O28: 99.4% positive (21.8K) | P28: =Table1_4[[#This Row],[Total Price]]*Table1_4[[#This Row],[ Sold]] -> 39048.58
A29: eBay | B29: Apple iPhone 14 256GB Factory Unlocked Very Good | C29: iPhone 14 | D29: 12-MONTH WARRANTY • FREE FAST SHIPPING • 30 DAY RETURNS | E29: Very Good | F29: 5 | G29: 6 | H29: 305 | I29: 113.91 | J29: =Table1_4[[#This Row],[Price]]+Table1_4[[#This Row],[Delivery charge]] -> 418.91 | K29: United States | L29: 0 | M29: No Discount | N29: savaydeals | O29: 99.8% positive (16.6K) | P29: =Table1_4[[#This Row],[Total Price]]*Table1_4[[#This Row],[ Sold]] -> 0
A30: eBay | B30: Apple iPhone 13 Mini 128GB - Fully Unlocked - VERY GOOD Condition | C30: iPhone 13 Mini | D30: No Warranty | E30: Very Good | F30: 4.5 | G30: 18 | H30: 218.9 | I30: 94.11 | J30: =Table1_4[[#This Row],[Price]]+Table1_4[[#This Row],[Delivery charge]] -> 313.01 | K30: United States | L30: 64 | M30: $5 off every 2 items with coupon | N30: gadget-solutions | O30: 99.4% positive (21.8K) | P30: =Table1_4[[#This Row],[Total Price]]*Table1_4[[#This Row],[ Sold]] -> 20032.64
A31: eBay | B31: Apple iPhone 14 PRO MAX 256GB - Fully Unlocked - VERY GOOD Condition | C31: iPhone 14 Pro Max | D31: No Warranty | E31: Very Good | F31: 4.5 | G31: 41 | H31: 499.2 | I31: 158.57 | J31: =Table1_4[[#This Row],[Price]]+Table1_4[[#This Row],[Delivery charge]] -> 657.77 | K31: United States | L31: 0 | M31: $5 off every 2 items with coupon | N31: gadget-solutions | O31: 99.4% positive (21.8K) | P31: =Table1_4[[#This Row],[Total Price]]*Table1_4[[#This Row],[ Sold]] -> 0
A32: eBay | B32: Apple iPhone 13 256GB - Fully Unlocked - VERY GOOD Condition | C32: iPhone 13 | D32: 1 YEAR WARRANTY🔥 FREE RETURNS🔥FREE FEDEX 2 DAY | E32: Very Good | F32: 5 | G32: 6 | H32: 278.4 | I32: 107.79 | J32: =Table1_4[[#This Row],[Price]]+Table1_4[[#This Row],[Delivery charge]] -> 386.19 | K32: United States | L32: 101 | M32: $5 off every 2 items with coupon | N32: gadget-solutions | O32: 99.4% positive (21.8K) | P32: =Table1_4[[#This Row],[Total Price]]*Table1_4[[#This Row],[ Sold]] -> 39005.19
A33: eBay | B33: Apple iPhone 12 Pro 128GB - Fully Unlocked - VERY GOOD Condition | C33: iPhone 12 Pro | D33: 1 YEAR WARRANTY🔥 FREE RETURNS🔥FREE 2 DAY SHIPPING | E33: Very Good | F33: 4.5 | G33: 10 | H33: 242.9 | I33: 99.63 | J33: =Table1_4[[#This Row],[Price]]+Table1_4[[#This Row],[Delivery charge]] -> 342.53 | K33: United States | L33: 326 | M33: $5 off every 2 items with coupon | N33: gadget-solutions | O33: 99.4% positive (21.8K) | P33: =Table1_4[[#This Row],[Total Price]]*Table1_4[[#This Row],[ Sold]] -> 111664.78
A34: eBay | B34: Apple iPhone 14 Plus A2632 128GB Unlocked - Very Good Refurbished | C34: iPhone 14 Plus | D34: No Warranty | E34: Very Good | F34: 4.5 | G34: 25 | H34: 294.99 | I34: 111.61 | J34: =Table1_4[[#This Row],[Price]]+Table1_4[[#This Row],[Delivery charge]] -> 406.6 | K34: United States | L34: 0 | M34: No Discount | N34: cellularstream | O34: 98.8% positive (173.8K) | P34: =Table1_4[[#This Row],[Total Price]]*Table1_4[[#This Row],[ Sold]] -> 0
A35: eBay | B35: Apple iPhone 15 Plus A2847 128GB Unlocked - Excellent Refurbished | C35: iPhone 15 Plus | D35: No Warranty | E35: Excellent | H35: 416.99 | I35: 142.29 | J35: =Table1_4[[#This Row],[Price]]+Table1_4[[#This Row],[Delivery charge]] -> 559.28 | K35: United States | L35: 0 | M35: No Discount | N35: cellularstream | O35: 98.8% positive (173.8K) | P35: =Table1_4[[#This Row],[Total Price]]*Table1_4[[#This Row],[ Sold]] -> 0
A36: eBay | B36: Apple iPhone 15 Plus A2847 128GB Unlocked - Very Good Refurbished | C36: iPhone 15 Plus | D36: No Warranty | E36: Very Good | H36: 408.99 | I36: 140.45 | J36: =Table1_4[[#This Row],[Price]]+Table1_4[[#This Row],[Delivery charge]] -> 549.44 | K36: United States | L36: 0 | M36: No Discount | N36: cellularstream | O36: 98.8% positive (173.8K) | P36: =Table1_4[[#This Row],[Total Price]]*Table1_4[[#This Row],[ Sold]] -> 0
A37: eBay | B37: Apple iPhone 13 A2482 128GB Midnight TracFone Locked Very Good | C37: iPhone 13 | D37: No Warranty | E37: Very Good | F37: 4 | G37: 1 | H37: 189.99 | I37: 90.08 | J37: =Table1_4[[#This Row],[Price]]+Table1_4[[#This Row],[Delivery charge]] -> 280.07 | K37: United States | L37: 55 | M37: No Discount | N37: sunnking | O37: 99.6% positive (165.4K) | P37: =Table1_4[[#This Row],[Total Price]]*Table1_4[[#This Row],[ Sold]] -> 15403.85
A38: eBay | B38: Apple iPhone 13 128GB Midnight A2482 ((Unlocked)) EXCELLENT | C38: iPhone 13 | D38: No Warranty | E38: Excellent | F38: 4.5 | G38: 108 | H38: 229.38 | I38: 96.52 | J38: =Table1_4[[#This Row],[Price]]+Table1_4[[#This Row],[Delivery charge]] -> 325.9 | K38: United States | L38: 20 | M38: No Discount | N38: soonersoft | O38: 99.2% positive (189.5K) | P38: =Table1_4[[#This Row],[Total Price]]*Table1_4[[#This Row],[ Sold]] -> 6518
A39: eBay | B39: Apple iPhone 12 64GB Unlocked Good Condition - All Colors | C39: iPhone 12 | D39: 12-MONTH WARRANTY • HAND TESTED • FREE SHIPPING | E39: Good | F39: 4.5 | G39: 89 | H39: 169.99 | I39: 82.86 | J39: =Table1_4[[#This Row],[Price]]+Table1_4[[#This Row],[Delivery charge]] -> 252.85 | K39: United States | L39: 373 | M39: No Discount | N39: itsworthmore | O39: 99.5% positive (149.3K) | P39: =Table1_4[[#This Row],[Total Price]]*Table1_4[[#This Row],[ Sold]] -> 94313.05
A40: eBay | B40: Apple iPhone 13 128GB Fully Unlocked - Very Good Condition | C40: iPhone 13 | D40: 1 YEAR WARRANTY🔥 FREE RETURNS🔥FREE 2 DAY SHIPPING | E40: Very Good | F40: 5 | G40: 53 | H40: 259.2 | I40: 103.37 | J40: =Table1_4[[#This Row],[Price]]+Table1_4[[#This Row],[Delivery charge]] -> 362.57 | K40: United States | L40: 443 | M40: $5 off every 2 items with coupon | N40: gadget-solutions | O40: 99.4% positive (21.8K) | P40: =Table1_4[[#This Row],[Total Price]]*Table1_4[[#This Row],[ Sold]] -> 160618.51
...

Sheet Ecommerce iphone resale
A1: Platform | B1: Model | C1: Model_family | D1: Generation_number | E1: is_pro | F1: Storage_options_gb | G1: Storage_gb_numeric | H1: Condition | I1: Price | J1: WasPrice | K1: Price_Discount_pct | L1: Available | M1: Sold | N1: Seller | O1: itemLocation | P1: City | Q1: US_States | R1: Country | S1: lastUpdated | T1: Month | U1: Year | V1: Revenue
A2: Kaggle | B2: Apple iPhone 14 Pro MAX 128GB FULLY Unlocked | C2: iPhone 14 Pro Max | D2: 14 | E2: TRUE | F2: 128GB | G2: 128 | H2: Used | I2: 726.99 | K2: No Discount | L2: 3 | M2: 0 | N2: Seller 019 | O2: Granada Hills, California, United States | P2: Granada Hills | Q2: California | R2: United States | S2: 46003 | T2: =TEXT(S2,"mmm") -> Dec | U2: 2025 | V2: 0
A3: Kaggle | B3: Apple iPhone 14 Pro MAX 512gb Deep purple (Factory Unlocked) | C3: iPhone 14 Pro Max | D3: 14 | E3: TRUE | F3: 512GB | G3: 512 | H3: Used | I3: 659.99 | K3: No Discount | L3: 2 | M3: 0 | N3: Seller 019 | O3: Granada Hills, California, United States | P3: Granada Hills | Q3: California | R3: United States | S3: 46091 | T3: =TEXT(S3,"mmm") -> Mar | U3: 2026 | V3: 0
A4: Kaggle | B4: Apple iPhone 14 Pro MAX 1 TB Deep purple (Factory Unlocked) | C4: iPhone 14 Pro Max | D4: 14 | E4: TRUE | F4: 1024GB | G4: 1024 | H4: Used | I4: 628.99 | K4: No Discount | L4: 0 | M4: 1 | N4: Seller 019 | O4: Granada Hills, California, United States | P4: Granada Hills | Q4: California | R4: United States | S4: 46065 | T4: =TEXT(S4,"mmm") -> Feb | U4: 2026 | V4: 628.99
A5: Kaggle | B5: Apple iPhone 14 Pro MAX 128gb GOLD (Factory Unlocked) | C5: iPhone 14 Pro Max | D5: 14 | E5: TRUE | F5: 128GB | G5: 128 | H5: Used | I5: 726.99 | K5: No Discount | L5: 2 | M5: 0 | N5: Seller 019 | O5: Granada Hills, California, United States | P5: Granada Hills | Q5: California | R5: United States | S5: 46003 | T5: =TEXT(S5,"mmm") -> Dec | U5: 2025 | V5: 0
A6: Kaggle | B6: Apple iPhone 14 Pro Max - 128 GB - ALL COLORS (Unlocked)- Very Good Refurb | C6: iPhone 14 Pro Max | D6: 14 | E6: TRUE | F6: 128GB | G6: 128 | H6: Very Good | I6: 469.99 | K6: No Discount | L6: 5 | M6: 2 | N6: Seller 063 | O6: Stafford, Texas, United States | P6: Stafford | Q6: Texas | R6: United States | S6: 46019 | T6: =TEXT(S6,"mmm") -> Dec | U6: 2025 | V6: 939.98
A7: Kaggle | B7: open box Apple iPhone 14 Pro MAX 256GB FULLY Unlocked | C7: iPhone 14 Pro Max | D7: 14 | E7: TRUE | F7: 256GB | G7: 256 | H7: Open Box | I7: 729.99 | K7: No Discount | L7: 0 | M7: 2 | N7: Seller 019 | O7: Granada Hills, California, United States | P7: Granada Hills | Q7: California | R7: United States | S7: 46003 | T7: =TEXT(S7,"mmm") -> Dec | U7: 2025 | V7: 1459.98
A8: Kaggle | B8: Apple iPhone 14+ plus 128gb BLACK color Factory Unlocked 1year ex warranty | C8: iPhone 14 | D8: 14 | E8: FALSE | F8: 128GB | G8: 128 | H8: Used | I8: 365.99 | K8: No Discount | L8: 2 | M8: 0 | N8: Seller 019 | O8: Granada Hills, California, United States | P8: Granada Hills | Q8: California | R8: United States | S8: 46067 | T8: =TEXT(S8,"mmm") -> Feb | U8: 2026 | V8: 0
A9: Kaggle | B9: Apple iPhone 14 -5G - 512GB Factory Unlocked GSM + CDMA - EXCELLENT | C9: iPhone 14 | D9: 14 | E9: FALSE | F9: 512GB | G9: 512 | H9: Excellent | I9: 397.48 | K9: No Discount | L9: 9 | M9: 30 | N9: Seller 064 | O9: Southfield, Michigan, United States | P9: Southfield | Q9: Michigan | R9: United States | S9: 46086 | T9: =TEXT(S9,"mmm") -> Mar | U9: 2026 | V9: 11924.4
A10: Kaggle | B10: open box Apple iPhone 14+ plus 128gb RED color Factory Unlocked | C10: iPhone 14 | D10: 14 | E10: FALSE | F10: 128GB | G10: 128 | H10: Open Box | I10: 399.99 | K10: No Discount | L10: 2 | M10: 0 | N10: Seller 019 | O10: Granada Hills, California, United States | P10: Granada Hills | Q10: California | R10: United States | S10: 46019 | T10: =TEXT(S10,"mmm") -> Dec | U10: 2025 | V10: 0
A11: Kaggle | B11: open box Apple iPhone 14 128gb RED color Factory Unlocked | C11: iPhone 14 | D11: 14 | E11: FALSE | F11: 128GB | G11: 128 | H11: Open Box | I11: 339.99 | K11: No Discount | L11: 5 | M11: 0 | N11: Seller 019 | O11: Granada Hills, California, United States | P11: Granada Hills | Q11: California | R11: United States | S11: 46042 | T11: =TEXT(S11,"mmm") -> Jan | U11: 2026 | V11: 0
A12: Kaggle | B12: OPEN BOX Apple iPhone 17 A3258 256GB 512GB BLACK SAGE LAVENDER BLUE (Unlocked) | C12: iPhone 17 | D12: 17 | E12: FALSE | F12: 256GB|512GB | G12: 256 | H12: Open Box | I12: 779 | K12: No Discount | L12: 0 | M12: 48 | N12: Seller 038 | O12: Dallas, Texas, United States | P12: Dallas | Q12: Texas | R12: United States | S12: 46101 | T12: =TEXT(S12,"mmm") -> Mar | U12: 2026 | V12: 37392
A13: Kaggle | B13: open box Apple iPhone 13 128GB Black color Unlocked battery | C13: iPhone 13 | D13: 13 | E13: FALSE | F13: 128GB | G13: 128 | H13: Open Box | I13: 321.99 | K13: No Discount | L13: 2 | M13: 0 | N13: Seller 019 | O13: Granada Hills, California, United States | P13: Granada Hills | Q13: California | R13: United States | S13: 46038 | T13: =TEXT(S13,"mmm") -> Jan | U13: 2026 | V13: 0
A14: Kaggle | B14: Apple iPhone 13 128GB Unlocked FACTORY UNLOCKED - EXCELLENT | C14: iPhone 13 | D14: 13 | E14: FALSE | F14: 128GB | G14: 128 | H14: Excellent | I14: 249.48 | K14: No Discount | L14: 0 | M14: 121 | N14: Seller 064 | O14: Southfield, Michigan, United States | P14: Southfield | Q14: Michigan | R14: United States | S14: 46103 | T14: =TEXT(S14,"mmm") -> Mar | U14: 2026 | V14: 30187.08
A15: Kaggle | B15: Apple iPhone 12 128GB Unlocked MODEL A2172 Blue color open box | C15: iPhone 12 | D15: 12 | E15: FALSE | F15: 128GB | G15: 128 | H15: Open Box | I15: 238.99 | K15: No Discount | L15: 1 | M15: 0 | N15: Seller 019 | O15: Granada Hills, California, United States | P15: Granada Hills | Q15: California | R15: United States | V15: 0
A16: Kaggle | B16: Apple iPhone 12 128GB Unlocked MODEL A2172 Blue color | C16: iPhone 12 | D16: 12 | E16: FALSE | F16: 128GB | G16: 128 | H16: Open Box | I16: 231.99 | K16: No Discount | L16: 1 | M16: 0 | N16: Seller 019 | O16: Granada Hills, California, United States | P16: Granada Hills | Q16: California | R16: United States | V16: 0
A17: Kaggle | B17: open box Apple iPhone 17 pro max 512GB Unlocked Deep Blue | C17: iPhone 17 Pro Max | D17: 17 | E17: TRUE | F17: 512GB | G17: 512 | H17: Open Box | I17: 1441.99 | K17: No Discount | L17: 1 | M17: 0 | N17: Seller 019 | O17: Granada Hills, California, United States | P17: Granada Hills | Q17: California | R17: United States | S17: 46106 | T17: =TEXT(S17,"mmm") -> Mar | U17: 2026 | V17: 0
A18: Kaggle | B18: open box Apple iPhone 13 128GB Blue Unlocked 1 year ex warranty | C18: iPhone 13 | D18: 13 | E18: FALSE | F18: 128GB | G18: 128 | H18: Open Box | I18: 329.99 | K18: No Discount | L18: 0 | M18: 1 | N18: Seller 019 | O18: Granada Hills, California, United States | P18: Granada Hills | Q18: California | R18: United States | V18: 329.99
A19: Kaggle | B19: NEW open box Apple iPhone 17 pro max 512GB Unlocked all colors | C19: iPhone 17 Pro Max | D19: 17 | E19: TRUE | F19: 512GB | G19: 512 | H19: Open Box | I19: 1444.99 | K19: No Discount | L19: 0 | M19: 1 | N19: Seller 019 | O19: Granada Hills, California, United States | P19: Granada Hills | Q19: California | R19: United States | S19: 46107 | T19: =TEXT(S19,"mmm") -> Mar | U19: 2026 | V19: 1444.99
A20: Kaggle | B20: Apple iPhone 12 64GB 128GB 256GB - Unlocked - All Colors - GOOD CONDITION | C20: iPhone 12 | D20: 12 | E20: FALSE | F20: 64GB|128GB|256GB | G20: 64 | H20: Good | I20: 135.99 | K20: No Discount | L20: 2 | M20: 481 | N20: Seller 109 | O20: Bolton, United Kingdom | P20: Bolton | R20: United Kingdom | S20: 46106 | T20: =TEXT(S20,"mmm") -> Mar | U20: 2026 | V20: 65411.19
A21: Kaggle | B21: Apple iPhone 14 Pro Max 256GB/512GB/1TB -Deep Purple UNLOCKED | C21: iPhone 14 Pro Max | D21: 14 | E21: TRUE | F21: 256GB|512GB|1024GB | G21: 256 | H21: Open Box | I21: 1119.2 | J21: 1399 | K21: 20 | L21: 0 | M21: 85 | N21: Seller 082 | O21: Washington, District Of Columbia, United States | P21: Washington | Q21: District Of Columbia | R21: United States | S21: 46042 | T21: =TEXT(S21,"mmm") -> Jan | U21: 2026 | V21: 95132
A22: Kaggle | B22: Brand new factory sealed Apple iPhone 14 Pro Max - 256GB - Gold (Unlocked) | C22: iPhone 14 Pro Max | D22: 14 | E22: TRUE | F22: 256GB | G22: 256 | H22: New | I22: 1406.5 | K22: No Discount | L22: 0 | M22: 2 | N22: Seller 638 | O22: Atlanta, Georgia, United States | P22: Atlanta | Q22: Georgia | R22: United States | S22: 45035 | T22: =TEXT(S22,"mmm") -> Apr | U22: 2023 | V22: 2813
A23: Kaggle | B23: Lot of 10 Apple iPhone 12 Unlocked 64gb Mixed Colors | C23: iPhone 12 | D23: 12 | E23: FALSE | F23: 64GB | G23: 64 | H23: Used | I23: 2110 | K23: No Discount | L23: 0 | M23: 2 | N23: Seller 332 | O23: Winter Garden, Florida, United States | P23: Winter Garden | Q23: Florida | R23: United States | S23: 46082 | T23: =TEXT(S23,"mmm") -> Mar | U23: 2026 | V23: 4220
A24: Kaggle | B24: Apple iPhone 14 Pro MAX 256GB FULLY Unlocked | C24: iPhone 14 Pro Max | D24: 14 | E24: TRUE | F24: 256GB | G24: 256 | H24: Used | I24: 669.99 | K24: No Discount | L24: 0 | M24: 3 | N24: Seller 019 | O24: Granada Hills, California, United States | P24: Granada Hills | Q24: California | R24: United States | S24: 46003 | T24: =TEXT(S24,"mmm") -> Dec | U24: 2025 | V24: 2009.97
A25: Kaggle | B25: Apple iPhone 12 Pro MAX 128gb Factory Unlocked 1 year ex warranty Graphite color | C25: iPhone 12 Pro Max | D25: 12 | E25: TRUE | F25: 128GB | G25: 128 | H25: Used | I25: 436.99 | K25: No Discount | L25: 2 | M25: 0 | N25: Seller 019 | O25: Granada Hills, California, United States | P25: Granada Hills | Q25: California | R25: United States | S25: 46003 | T25: =TEXT(S25,"mmm") -> Dec | U25: 2025 | V25: 0
A26: Kaggle | B26: Apple iPhone 14 Pro MAX 512gb black color (Factory Unlocked) | C26: iPhone 14 Pro Max | D26: 14 | E26: TRUE | F26: 512GB | G26: 512 | H26: Used | I26: 659.99 | K26: No Discount | L26: 2 | M26: 0 | N26: Seller 019 | O26: Granada Hills, California, United States | P26: Granada Hills | Q26: California | R26: United States | S26: 46091 | T26: =TEXT(S26,"mmm") -> Mar | U26: 2026 | V26: 0
A27: Kaggle | B27: open box Apple iPhone 14 Pro MAX 128gb Deep purple Factory Unlocked | C27: iPhone 14 Pro Max | D27: 14 | E27: TRUE | F27: 128GB | G27: 128 | H27: Open Box | I27: 734.99 | K27: No Discount | L27: 2 | M27: 0 | N27: Seller 019 | O27: Granada Hills, California, United States | P27: Granada Hills | Q27: California | R27: United States | S27: 46003 | T27: =TEXT(S27,"mmm") -> Dec | U27: 2025 | V27: 0
A28: Kaggle | B28: Apple iPhone 14 128gb white color Factory Unlocked | C28: iPhone 14 | D28: 14 | E28: FALSE | F28: 128GB | G28: 128 | H28: Used | I28: 329.99 | K28: No Discount | L28: 2 | M28: 1 | N28: Seller 019 | O28: Granada Hills, California, United States | P28: Granada Hills | Q28: California | R28: United States | S28: 46024 | T28: =TEXT(S28,"mmm") -> Jan | U28: 2026 | V28: 329.99
A29: Kaggle | B29: Apple iPhone 14 - 128GB fully Unlocked open box | C29: iPhone 14 | D29: 14 | E29: FALSE | F29: 128GB | G29: 128 | H29: Open Box | I29: 338.99 | K29: No Discount | L29: 4 | M29: 0 | N29: Seller 019 | O29: Granada Hills, California, United States | P29: Granada Hills | Q29: California | R29: United States | S29: 46067 | T29: =TEXT(S29,"mmm") -> Feb | U29: 2026 | V29: 0
A30: Kaggle | B30: Apple iPhone 14 A2649 iOS Smartphone 128GB/ 256GB-UNLOCKED/AT&T/T-Mobile/Verizon | C30: iPhone 14 | D30: 14 | E30: FALSE | F30: 128GB|256GB | G30: 128 | H30: Excellent | I30: 349.99 | K30: No Discount | L30: 0 | M30: 7 | N30: Seller 186 | O30: Chicago, Illinois, United States | P30: Chicago | Q30: Illinois | R30: United States | S30: 45989 | T30: =TEXT(S30,"mmm") -> Nov | U30: 2025 | V30: 2449.93
A31: Kaggle | B31: New Sealed Apple iPhone 14 Pro Max/13 ProMax/SE 3rd/14/13/13 Mini/12 Mini 5G LOT | C31: iPhone 14 Pro Max | D31: 14 | E31: TRUE | F31: 128GB | G31: 128 | H31: New | I31: 314.11 | K31: No Discount | L31: 0 | M31: 1 | N31: Seller 291 | O31: Whippany, New Jersey, United States | P31: Whippany | Q31: New Jersey | R31: United States | S31: 46109 | T31: =TEXT(S31,"mmm") -> Mar | U31: 2026 | V31: 314.11
A32: Kaggle | B32: Apple iPhone 15 256GB Factory Unlocked CDMA + GSM - Excellent | C32: iPhone 15 | D32: 15 | E32: FALSE | F32: 256GB | G32: 256 | H32: Excellent | I32: 419.48 | K32: No Discount | L32: 5 | M32: 85 | N32: Seller 064 | O32: Southfield, Michigan, United States | P32: Southfield | Q32: Michigan | R32: United States | S32: 46109 | T32: =TEXT(S32,"mmm") -> Mar | U32: 2026 | V32: 35655.8
A33: Kaggle | B33: 💯New Sealed Apple iPhone 13 MINI A2481 128GB /256GB Factory Unlocked Smartphone | C33: iPhone 13 Mini | D33: 13 | E33: FALSE | F33: 128GB|256GB | G33: 128 | H33: New | I33: 321.88 | K33: No Discount | L33: 2 | M33: 5 | N33: Seller 291 | O33: Whippany, New Jersey, United States | P33: Whippany | Q33: New Jersey | R33: United States | S33: 46109 | T33: =TEXT(S33,"mmm") -> Mar | U33: 2026 | V33: 1609.4
... A35: Kaggle | B35: New Apple iPhone 13/14/12 Mini/13 Mini /14 Pro Max/SE 3rd Unlocked 2yr-wty LOT | C35: iPhone 13 | D35: 13 | E35: FALSE | F35: 128GB | G35: 128 | H35: New | I35: 314.11 | K35: No Discount | L35: 0 | M35: 2 | N35: Seller 291 | O35: Brooklyn, New York, United States | P35: Brooklyn | Q35: New York | R35: United States | S35: 46109 | T35: =TEXT(S35,"mmm") -> Mar | U35: 2026 | V35: 628.22
A36: Kaggle | B36: New Sealed Unlocked Apple iPhone 17 Pro Max 6.9-inch A3257 Deep Blue 2TB | C36: iPhone 17 Pro Max | D36: 17 | E36: TRUE | F36: 2048GB | G36: 2048 | H36: New | I36: 2559.96 | J36: 3199.95 | K36: 20 | L36: 0 | M36: 1 | N36: Seller 082 | O36: Fairfax, Virginia, United States | P36: Fairfax | Q36: Virginia | R36: United States | S36: 46064 | T36: =TEXT(S36,"mmm") -> Feb | U36: 2026 | V36: 2559.96
A37: Kaggle | B37: Apple iPhone 14+ plus 128GB A2632 Unlocked open box | C37: iPhone 14 | D37: 14 | E37: FALSE | F37: 128GB | G37: 128 | H37: Open Box | I37: 394.99 | K37: No Discount | L37: 1 | M37: 0 | N37: Seller 019 | O37: Granada Hills, California, United States | P37: Granada Hills | Q37: California | R37: United States | S37: 46067 | T37: =TEXT(S37,"mmm") -> Feb | U37: 2026 | V37: 0
A38: Kaggle | B38: Apple iPhone 14 Pro Max, 128/256GB - Grade B - All Colors | C38: iPhone 14 Pro Max | D38: 14 | E38: TRUE | F38: 256GB | G38: 256 | H38: Used | I38: 379.87 | K38: No Discount | L38: 1 | M38: 0 | N38: Seller 099 | O38: Scottsdale, Arizona, United States | P38: Scottsdale | Q38: Arizona | R38: United States | S38: 46045 | T38: =TEXT(S38,"mmm") -> Jan | U38: 2026 | V38: 0
A39: Kaggle | B39: Apple iPhone 14 Pro Max, 128/256GB - Grade B+ All Colors ✅ Ships Today! | C39: iPhone 14 Pro Max | D39: 14 | E39: TRUE | F39: 256GB | G39: 256 | H39: Used | I39: 589.99 | K39: No Discount | L39: 1 | M39: 0 | N39: Seller 099 | O39: Scottsdale, Arizona, United States | P39: Scottsdale | Q39: Arizona | R39: United States | S39: 46045 | T39: =TEXT(S39,"mmm") -> Jan | U39: 2026 | V39: 0
A40: Kaggle | B40: Apple iPhone 14 Pro Max, 128/256GB - Grade A- All Colors ✅ Ships Today! | C40: iPhone 14 Pro Max | D40: 14 | E40: TRUE | F40: 256GB | G40: 256 | H40: Used | I40: 649.99 | K40: No Discount | L40: 1 | M40: 0 | N40: Seller 099 | O40: Scottsdale, Arizona, United States | P40: Scottsdale | Q40: Arizona | R40: United States | S40: 46045 | T40: =TEXT(S40,"mmm") -> Jan | U40: 2026 | V40: 0
A41: Kaggle | B41: Apple iPhone 14, iPhone 14 Plus, 128GB/256GB, Grade A, All Colors, Ships Today! | C41: iPhone 14 Plus | D41: 14 | E41: FALSE | F41: 128GB|256GB | G41: 128 | H41: Used | I41: 409.87 | K41: No Discount | L41: 1 | M41: 0 | N41: Seller 099 | O41: Scottsdale, Arizona, United States | P41: Scottsdale | Q41: Arizona | R41: United States | S41: 46045 | T41: =TEXT(S41,"mmm") -> Jan | U41: 2026 | V41: 0
...

Sheet DASHBOARD
A1: E-commerce iphone Resale Market Intelligence
C7: Units Sold | F7: Units Available | I7: Total Revenue | L7: Total Avg Revenue | O7: Total iphone Models | R7: Total no of Storage variant | U7: Best Selling Model | X7: Seller Count | AA7: Total no of US States | AD7: Total no of countries
C9: =SUM('Ecommerce iphone resale'!M2:M1678) -> 147128 | F9: =SUM('Ecommerce iphone resale'!L2:L1678) -> 4216 | I9: =SUM('Ecommerce iphone resale'!V1:V1678) -> 67602451 | L9: =AVERAGE('Ecommerce iphone resale'!V2:V1678) -> 40311.539 | O9: =COUNTA(_xlfn.UNIQUE('Ecommerce iphone resale'!C2:C1678)) -> 17 | R9: =COUNTA(_xlfn.UNIQUE('Ecommerce iphone resale'!G2:G1678)) -> 6 | U9: iphone 15 Pro Max | X9: =COUNTA(_xlfn.UNIQUE('Ecommerce iphone resale'!N2:N1678)) -> 240 | AA9: =COUNTA(_xlfn.UNIQUE('Ecommerce iphone resale'!Q2:Q1678)) -> 33 | AD9: =COUNTA(_xlfn.UNIQUE('Ecommerce iphone resale'!R2:R1678)) -> 10
U11: =GETPIVOTDATA("Revenue",'Top 5 performing models '!$A$3,"Model_family","iPhone 15 Pro Max") -> 27567566

Sheet Platform camparison
A1: PLATFORM COMPARISON
I7: Total Units Sold (eBay) | L7: Total Units Sold (Backmarket) | O7: Total Units Sold (Kaggle)
I9: =SUM(eBay!L2:L2034) -> 64692 | L9: =SUM(Backmarket!D2:D69) -> 46290 | O9: =SUM('Ecommerce iphone resale'!M2:M1678) -> 147128
I12: =SUM(eBay!P2:P2034) -> 28212467 | L12: =SUM(Backmarket!G2:G69) -> 12577556 | O12: =SUM('Ecommerce iphone resale'!V2:V1678) -> 67602451

Sheet Product counts
B4: Row Labels | C4: Sum of Available | D4: Sum of Sold
B5: 12 | C5: 669 | D5: 16422
B6: 13 | C6: 1119 | D6: 14096
B7: 14 | C7: 1085 | D7: 15435 | H7: Total no of sold products | L7: Total no of Avl products
B8: 15 | C8: 374 | D8: 90612 | H8: =SUM('Ecommerce iphone resale'!M1:M1678) -> 147128 | L8: =SUM('Ecommerce iphone resale'!L2:L1678) -> 4216
B9: 16 | C9: 175 | D9: 6640
B10: 17 | C10: 794 | D10: 3923
H11: Pros Count | L11: Non-Pros Count
H12: =COUNTIF('Ecommerce iphone resale'!E1:E1678,"TRUE") -> 333 | L12: =COUNTIF('Ecommerce iphone resale'!E2:E1678,"FALSE") -> 1344

Sheet Top 5 performing models 
A3: Row Labels | B3: Sum of Revenue
A4: iPhone 16 | B4: 3855210
A5: iPhone 14 | B5: 3967545.5
A6: iPhone 15 | B6: 7523231.6
A7: iPhone 15 Pro | B7: 9662011.4
A8: iPhone 15 Pro Max | B8: 27567566
C22: =B26-B25 -> 73.195
A23: iphone 14 | B23: 297.71206 | C23: The Price difference between the iphone 15 pro and iphone 15 Pro Max is just $73.20
A24: iphone 15 | B24: 407.06846
A25: iphone 15 Pro | B25: 495.795
A26: iphone 15 Pro Max | B26: 568.99
A27: iphone 16 | B27: 586.53137

Sheet Least 5 iphone models
A2: Row Labels | B2: Sum of Revenue
A3: iPhone 12 Mini | B3: 3527.02
A4: iPhone 13 Pro Max | B4: 4159.83
A5: iPhone 12 Pro | B5: 7789.8
A6: iPhone 14 Pro Max | B6: 522833.15
A7: iPhone 14 Plus | B7: 681755.58

Sheet Price comparison
B3: Model | C3: Kaggle | D3: eBay | E3: Backmarket
B4: iphone 12 | C4: 175.05243 | D4: 297.70803 | E4: 177.4975
B5: iphone 12 mini | C5: 324.35857 | D5: 284.35035 | E5: 163
B6: iphone 12 Pro | C6: 326.07833 | D6: 382.65487 | E6: 264.16
B7: iphone 12 Pro Max | C7: 388.41522 | D7: 476.74148 | E7: 323.2975
B8: iphone 13 | C8: 278.7781 | D8: 374.13188 | E8: 242.875
B9: iphone 13 mini | C9: 320.03556 | D9: 394.87063 | E9: 249.75
B10: iphone 13 Pro max | C10: 343.57667 | D10: 583.97424 | E10: 425.99
B11: iphone 14 | C11: 297.71206 | D11: 418.19738 | E11: 268.75
B12: iphone 14 Plus | C12: 392.48237 | D12: 448.24292 | E12: 303.485
B13: iphone 14 Pro Max | C13: 634.99886 | D13: 653.2259 | E13: 426.14
B14: iphone 15 | C14: 407.06846 | D14: 537.51583 | E14: 368.44
B15: iphone 15 Plus | C15: 415.01 | D15: 549.41471 | E15: 434.84
... B20: iphone 17 Pro Max | C20: 1349.7052 | D20: 1276.37 | E20: 1185.6667
B27: Model | C27: eBay VS Kaggle | D27: Kaggle VS Backmarket | E27: eBay VS Backmarket
B28: iphone 12 | C28: =C4-D4 -> -122.6556 | D28: =E4-D4 -> -120.21053 | E28: =D4-E4 -> 120.21053
B29: iphone 12 mini | C29: =C5-D5 -> 40.008224 | D29: =C5-E5 -> 161.35857 | E29: =D5-E5 -> 121.35035
B30: iphone 12 Pro | C30: =C6-D6 -> -56.576538 | D30: =C6-E6 -> 61.918333 | E30: =D6-E6 -> 118.49487
B31: iphone 12 Pro Max | C31: =C7-D7 -> -88.326264 | D31: =C7-E7 -> 65.117717 | E31: =D7-E7 -> 153.44398
B32: iphone 13 | C32: =C8-D8 -> -95.353778 | D32: =C8-E8 -> 35.903102 | E32: =D8-E8 -> 131.25688
B33: iphone 13 mini | C33: =C9-D9 -> -74.835076 | D33: =C9-E9 -> 70.285556 | E33: =D9-E9 -> 145.12063
B34: iphone 13 Pro max | C34: =C10-D10 -> -240.39757 | D34: =C10-E10 -> -82.413333 | E34: =D10-E10 -> 157.98424
B35: iphone 14 | C35: =C11-D11 -> -120.48532 | D35: =C11-E11 -> 28.962061 | E35: =D11-E11 -> 149.44738
B36: iphone 14 Plus | C36: =C12-D12 -> -55.760552 | D36: =C12-E12 -> 88.997373 | E36: =D12-E12 -> 144.75792
B37: iphone 14 Pro Max | C37: =C13-D13 -> -18.22704 | D37: =C13-E13 -> 208.85886 | E37: =D13-E13 -> 227.0859
B38: iphone 15 | C38: =C14-D14 -> -130.44737 | D38: =C14-E14 -> 38.628462 | E38: =D14-E14 -> 169.07583
B39: iphone 15 Plus | C39: =C15-D15 -> -134.40471 | D39: =C15-E15 -> -19.83 | E39: =D15-E15 -> 114.57471
B40: iphone 15 Pro | C40: =C16-D16 -> -195.13629 | D40: =C16-E16 -> 6.0475 | E40: =D16-E16 -> 201.18379
... B44: iphone 17 Pro Max | C44: =C20-D20 -> 73.335213 | D44: =C20-E20 -> 164.03855 | E44: =D20-E20 -> 90.703333
C45: Highest selling price(ebay) | D45: Mid level(Kaggle) | E45: Cheapest price(Backmarket)

Sheet Top 5 US states
B3: Row Labels | C3: Sum of Revenue
B4: Texas | C4: 45804582
B5: New York | C5: 9093082.7
B6: Kansas | C6: 5420041.2
B7: California | C7: 2590486.5
B8: New Jersey | C8: 1860004.8

Sheet Least 10 US states
B3: Row Labels | C3: Sum of Revenue
B4: Hawaii | C4: 0
B5: North Carolina | C5: 0
B6: Oregon | C6: 0
B7: Oklahoma | C7: 403
B8: Colorado | C8: 479.99
B9: Louisiana | C9: 649
B10: Tennessee | C10: 779.95
B11: Kentucky | C11: 839.85
B12: Missouri | C12: 1158.99
B13: Minnesota | C13: 1200
B26: Row Labels | C26: Sum of Revenue | D26: Average of Price | E26: Row Labels | F26: Sum of Revenue | G26: Average of Price
B27: Hawaii | C27: 0 | D27: 784.13 | E27: Texas | F27: 45804582 | G27: 240.22
C28: 0 | D28: 153 | E28: New York | F28: 8653155.7 | G28: 404.6138
B29: Oregon | C29: 0 | D29: 1134.97 | E29: Kansas | F29: 5420041.2 | G29: 453.44107
B30: North Carolina | C30: 0 | D30: 498 | E30: California | F30: 2590486.5 | G30: 564.88937
B31: Oklahoma | C31: 403 | D31: 451.495 | E31: New Jersey | F31: 1860004.8 | G31: 440.30095
B32: Colorado | C32: 479.99 | D32: 479.99
B33: Louisiana | C33: 649 | D33: 649
B34: Tennessee | C34: 779.95 | D34: 779.95
B35: Kentucky | C35: 839.85 | D35: 369.63333
B36: Missouri | C36: 1158.99 | D36: 586.33
B37: Minnesota | C37: 1200 | D37: 699.995

Sheet Revenue by country
A3: Row Labels | B3: Sum of Revenue
A4: United States | B4: 67081969
A5: China | B5: 112984.59
A6: South Korea | B6: 104870.18
A7: United Kingdom | B7: 86729.16
A8: Australia | B8: 78369.96

Sheet Most sold st variant
A3: Row Labels | B3: Sum of Revenue
A4: 256 | B4: 41781405
A5: 128 | B5: 20242025
A6: 512 | B6: 4828587.8
A7: 64 | B7: 674714.95
A8: 1024 | B8: 69035.14
A9: 2048 | B9: 6682.95

Sheet Most Sold condition
B3: Row Labels | C3: Sum of Sold
B4: For Parts Or Not Working | C4: 113
B5: Good | C5: 3468
B6: Open Box | C6: 4384
B7: New | C7: 5821
B8: Excellent | C8: 14511
B9: Used | C9: 21887
B10: Very Good | C10: 96944

Sheet Instock & NA
B2: Row Labels | C2: Sum of Available
B3: iPhone 13 Mini | C3: 752
B4: iPhone 14 | C4: 597
B5: iPhone 12 | C5: 470
B6: iPhone 17 | C6: 444
B7: iPhone 13 | C7: 352
B8: iPhone 17 Pro Max | C8: 350
B9: iPhone 14 Pro Max | C9: 337
B10: iPhone 15 | C10: 231
B11: iPhone 16 | C11: 175
B12: iPhone 12 Pro Max | C12: 165
B13: iPhone 14 Plus | C13: 151
B14: iPhone 15 Plus | C14: 116
... B19: iPhone 15 Pro Max | C19: 0

Sheet Most Sold Sellers
B4: Row Labels | C4: Sum of Revenue
B5: Seller 050 | C5: 41555087
B6: Seller 165 | C6: 5420041.2
B7: Seller 061 | C7: 4775219.9
B8: Seller 195 | C8: 3229557.4
B9: Seller 114 | C9: 2923017.6
B10: Seller 146 | C10: 2190694.2
B11: Seller 025 | C11: 999503.75
B12: Seller 023 | C12: 434397
B13: Seller 147 | C13: 420305
B14: Seller 084 | C14: 393088.8

Sheet Most sold platform
B2: Model | C2: Kaggle | D2: eBay | E2: Backmarket
B3: iPhone 12 | C3: 9614 | D3: 238 | E3: 9967
B4: iPhone 12 Mini | C4: 11 | D4: 115 | E4: 4278
B5: iPhone 12 Pro | C5: 24 | D5: 78 | E5: 3733
B6: iPhone 12 Pro Max | C6: 6773 | D6: 54 | E6: 3421
B7: iPhone 13 | C7: 9870 | D7: 282 | E7: 6021
B8: iPhone 13 Mini | C8: 4213 | D8: 95 | E8: 2311
B9: iPhone 13 Pro Max | C9: 13 | D9: 85 | E9: 2492
B10: iPhone 14 | C10: 12742 | D10: 271 | E10: 4078
B11: iPhone 14 Plus | C11: 1818 | D11: 106 | E11: 1706
B12: iPhone 14 Pro Max | C12: 875 | D12: 78 | E12: 1659
B13: iPhone 15 | C13: 18730 | D13: 211 | E13: 2010
B14: iPhone 15 Plus | C14: 3480 | D14: 85 | E14: 1166
... B19: iPhone 17 Pro Max | C19: 2832 | D19: 1 | E19: 72

Sheet Platform Revenue Comparison
A1: Model | B1: Kaggle | C1: eBay | D1: Backmarket
A2: iPhone 12 | B2: 1809323.6 | C2: 2696546.8 | D2: 1707684.3
A3: iPhone 12 Mini | B3: 3527.02 | C3: 749778.9 | D3: 629414
A4: iPhone 12 Pro | B4: 7789.8 | C4: 1646549.8 | D4: 912535.08
A5: iPhone 12 Pro Max | B5: 2273560.3 | C5: 636954.45 | D5: 1091344.8
A6: iPhone 13 | B6: 2637286.5 | C6: 4199196.9 | D6: 1389519
A7: iPhone 13 Mini | B7: 1134297.8 | C7: 525629.63 | D7: 488655
A8: iPhone 13 Pro Max | B8: 4159.83 | C8: 724.11 | D8: 957552.48
A9: iPhone 14 | B9: 3967545.5 | C9: 3575027.5 | D9: 1073606
A10: iPhone 14 Plus | B10: 681755.58 | C10: 1341986.2 | D10: 518177.32
A11: iPhone 14 Pro Max | B11: 522833.15 | C11: 1542277.7 | D11: 733934.84
A12: iPhone 15 | B12: 7523231.6 | C12: 2528053.3 | D12: 739768.48
A13: iPhone 15 Plus | B13: 1437093 | C13: 923986.56 | D13: 455901.96
... A18: iPhone 17 Pro Max | B18: 3645022.7 | C18: 7658.22 | D18: 100238
